Traceback (most recent call last):
  File "/Users/tawneykirkland/credit/modeling/model_training.py", line 112, in <module>
    main()
  File "/Users/tawneykirkland/credit/modeling/model_training.py", line 102, in main
    model_pipeline = train_model()
                     ^^^^^^^^^^^^^
  File "/Users/tawneykirkland/credit/modeling/model_training.py", line 50, in train_model
    X = df.drop(['serious_delinquency', 'COUNT_6089_DAYS_PAST_DUE', 'COUNT_3059_DAYS_PAST_DUE'], axis=1)
        ^^^^^^^^^^^^^^^^^^^^^^^^^^^^^^^^^^^^^^^^^^^^^^^^^^^^^^^^^^^^^^^^^^^^^^^^^^^^^^^^^^^^^^^^^^^^^^^^
  File "/Users/tawneykirkland/credit/venv/lib/python3.11/site-packages/pandas/core/frame.py", line 5581, in drop
    return super().drop(
           ^^^^^^^^^^^^^
  File "/Users/tawneykirkland/credit/venv/lib/python3.11/site-packages/pandas/core/generic.py", line 4788, in drop
    obj = obj._drop_axis(labels, axis, level=level, errors=errors)
          ^^^^^^^^^^^^^^^^^^^^^^^^^^^^^^^^^^^^^^^^^^^^^^^^^^^^^^^^
  File "/Users/tawneykirkland/credit/venv/lib/python3.11/site-packages/pandas/core/generic.py", line 4830, in _drop_axis
    new_axis = axis.drop(labels, errors=errors)
               ^^^^^^^^^^^^^^^^^^^^^^^^^^^^^^^^
  File "/Users/tawneykirkland/credit/venv/lib/python3.11/site-packages/pandas/core/indexes/base.py", line 7070, in drop
    raise KeyError(f"{labels[mask].tolist()} not found in axis")
KeyError: "['serious_delinquency'] not found in axis"
